<?xml version="1.0"?>
<sdf version='1.7'>
  <model name='uvc_robot_v3'>
  <static>false</static>
  
  <!-- ****************** ROBOT BASE FOOTPRINT ***************************  -->
  <pose>0.0 0.0 0.0 0.0 0.0 0.0</pose>
  <link name="base_footprint"/>
  
  <!-- ********************* All Links ********************* -->
    <link name='base_link'>

      <inertial>
        <pose>0 0 0.479 0 0 0</pose>
<!--        <mass>200</mass>
        <inertia>
          <ixx>0.001</ixx>
          <ixy>0.000</ixy>
          <ixz>0.000</ixz>
          <iyy>0.001</iyy>
          <iyz>0.000</iyz>
          <izz>0.001</izz>
        </inertia>-->
      </inertial>
      
      <collision name='base_link_collision'>
        <pose>0 0 0 0 0 0</pose>
        <geometry>
          <mesh>
            <scale>1 1 1</scale>
            <uri>model://description/meshes/base_link.STL</uri>
          </mesh>
        </geometry>
      </collision>
      
      <visual name='base_link_visual'>
        <pose>0 0 0 0 0 0</pose>
        <geometry>
          <mesh>
            <scale>1 1 1</scale>
            <uri>model://description/meshes/base_link.STL</uri>
          </mesh>
        </geometry>
        <material>
          <script>
            <name>Gazebo/Red</name>
            <uri>file://media/materials/scripts/gazebo.material</uri>
          </script>
        </material>
      </visual>
    </link>
    
    <link name='link_left'>
      <pose relative_to='joint_left'>0 0 0 0 0 0</pose>

      <inertial>
        <pose>0 -0.025 0 0 0 0</pose>
<!--        <mass>1</mass>
        <inertia>
          <ixx>0.001</ixx>
          <ixy>0.000</ixy>
          <ixz>0.000</ixz>
          <iyy>0.001</iyy>
          <iyz>0.000</iyz>
          <izz>0.001</izz>
        </inertia>-->
      </inertial>

      <collision name='link_left_collision'>
        <pose>0 0 0 0 0 0</pose>
        <geometry>
          <mesh>
            <scale>1 1 1</scale>
            <uri>model://description/meshes/link_left.STL</uri>
          </mesh>
        </geometry>
      </collision>

      <visual name='link_left_visual'>
        <pose>0 0 0 0 0 0</pose>
        <geometry>
          <mesh>
            <scale>1 1 1</scale>
            <uri>model://description/meshes/link_left.STL</uri>
          </mesh>
        </geometry>
        <material>
          <script>
            <name>Gazebo/Green</name>
            <uri>file://media/materials/scripts/gazebo.material</uri>
          </script>
        </material>
      </visual>
    </link>
    
    <link name='link_right'>
      <pose relative_to='joint_right'>0 0 0 0 0 0</pose>

      <inertial>
        <pose>0 0.025 0 0 0 0</pose>
<!--        <mass>1</mass>
        <inertia>
          <ixx>0.001</ixx>
          <ixy>0.000</ixy>
          <ixz>0.000</ixz>
          <iyy>0.001</iyy>
          <iyz>0.000</iyz>
          <izz>0.001</izz>
        </inertia>-->
      </inertial>

      <collision name='link_right_collision'>
        <pose>0 0 0 0 0 0</pose>
        <geometry>
          <mesh>
            <scale>1 1 1</scale>
            <uri>model://description/meshes/link_right.STL</uri>
          </mesh>
        </geometry>
      </collision>

      <visual name='link_right_visual'>
        <pose>0 0 0 0 0 0</pose>
        <geometry>
          <mesh>
            <scale>1 1 1</scale>
            <uri>model://description/meshes/link_right.STL</uri>
          </mesh>
        </geometry>
        <material>
          <script>
            <name>Gazebo/Green</name>
            <uri>file://media/materials/scripts/gazebo.material</uri>
          </script>
        </material>
      </visual>
    </link>
    
    <link name='link_castor_fl'>
      <pose relative_to='joint_castor_fl'>0 0 0 0 0 0</pose>

      <inertial>
        <pose>0 -0.449 -0.018 0 0 0</pose>
<!--        <mass>1</mass>
        <inertia>
          <ixx>0.001</ixx>
          <ixy>0.000</ixy>
          <ixz>0.000</ixz>
          <iyy>0.001</iyy>
          <iyz>0.000</iyz>
          <izz>0.001</izz>
        </inertia>-->
      </inertial>

      <collision name='link_castor_fl_collision'>
        <pose>0 0 0 0 0 0</pose>
        <geometry>
          <mesh>
            <scale>1 1 1</scale>
            <uri>model://description/meshes/link_castor_fl.STL</uri>
          </mesh>
        </geometry>
        <surface>
          <friction>
            <ode>
              <mu>0.01</mu>
              <mu2>0.01</mu2>
              <slip1>1.0</slip1>
              <slip2>1.0</slip2>
            </ode>
          </friction>
        </surface>
      </collision>

      <visual name='link_castor_fl_visual'>
        <pose>0 0 0 0 0 0</pose>
        <geometry>
          <mesh>
            <scale>1 1 1</scale>
            <uri>model://description/meshes/link_castor_fl.STL</uri>
          </mesh>
        </geometry>
        <material>
          <script>
            <name>Gazebo/Blue</name>
            <uri>file://media/materials/scripts/gazebo.material</uri>
          </script>
        </material>
      </visual>
    </link>
    
    <link name='link_castor_fr'>
      <pose relative_to='joint_castor_fr'>0 0 0 0 0 0</pose>

      <inertial>
        <pose>0 0.449 -0.018 0 0 0</pose>
<!--        <mass>1</mass>
        <inertia>
          <ixx>0.001</ixx>
          <ixy>0.000</ixy>
          <ixz>0.000</ixz>
          <iyy>0.001</iyy>
          <iyz>0.000</iyz>
          <izz>0.001</izz>
        </inertia>-->
      </inertial>

      <collision name='link_castor_fr_collision'>
        <pose>0 0 0 0 0 0</pose>
        <geometry>
          <mesh>
            <scale>1 1 1</scale>
            <uri>model://description/meshes/link_castor_fr.STL</uri>
          </mesh>
        </geometry>
        <surface>
          <friction>
            <ode>
              <mu>0.01</mu>
              <mu2>0.01</mu2>
              <slip1>1.0</slip1>
              <slip2>1.0</slip2>
            </ode>
          </friction>
        </surface>
      </collision>

      <visual name='link_castor_fr_visual'>
        <pose>0 0 0 0 0 0</pose>
        <geometry>
          <mesh>
            <scale>1 1 1</scale>
            <uri>model://description/meshes/link_castor_fr.STL</uri>
          </mesh>
        </geometry>
        <material>
          <script>
            <name>Gazebo/Blue</name>
            <uri>file://media/materials/scripts/gazebo.material</uri>
          </script>
        </material>
      </visual>
    </link>
    
    <link name='link_castor_rl'>
      <pose relative_to='joint_castor_rl'>0 0 0 0 0 0</pose>

      <inertial>
        <pose>0 -0.449 -0.018 0 0 0</pose>
<!--        <mass>1</mass>
        <inertia>
          <ixx>0.001</ixx>
          <ixy>0.000</ixy>
          <ixz>0.000</ixz>
          <iyy>0.001</iyy>
          <iyz>0.000</iyz>
          <izz>0.001</izz>
        </inertia>-->
      </inertial>

      <collision name='link_castor_rl_collision'>
        <pose>0 0 0 0 0 0</pose>
        <geometry>
          <mesh>
            <scale>1 1 1</scale>
            <uri>model://description/meshes/link_castor_rl.STL</uri>
          </mesh>
        </geometry>
        <surface>
          <friction>
            <ode>
              <mu>0.01</mu>
              <mu2>0.01</mu2>
              <slip1>1.0</slip1>
              <slip2>1.0</slip2>
            </ode>
          </friction>
        </surface>
      </collision>

      <visual name='link_castor_rl_visual'>
        <pose>0 0 0 0 0 0</pose>
        <geometry>
          <mesh>
            <scale>1 1 1</scale>
            <uri>model://description/meshes/link_castor_rl.STL</uri>
          </mesh>
        </geometry>
        <material>
          <script>
            <name>Gazebo/Blue</name>
            <uri>file://media/materials/scripts/gazebo.material</uri>
          </script>
        </material>
      </visual>
    </link>
    
    <link name='link_castor_rr'>
      <pose relative_to='joint_castor_rr'>0 0 0 0 0 0</pose>

      <inertial>
        <pose>0 0.449 -0.018 0 0 0</pose>
<!--        <mass>1</mass>
        <inertia>
          <ixx>0.001</ixx>
          <ixy>0.000</ixy>
          <ixz>0.000</ixz>
          <iyy>0.001</iyy>
          <iyz>0.000</iyz>
          <izz>0.001</izz>
        </inertia>-->
      </inertial>

      <collision name='link_castor_rr_collision'>
        <pose>0 0 0 0 0 0</pose>
        <geometry>
          <mesh>
            <scale>1 1 1</scale>
            <uri>model://description/meshes/link_castor_rr.STL</uri>
          </mesh>
        </geometry>
        <surface>
          <friction>
            <ode>
              <mu>0.01</mu>
              <mu2>0.01</mu2>
              <slip1>1.0</slip1>
              <slip2>1.0</slip2>
            </ode>
          </friction>
        </surface>
      </collision>

      <visual name='link_castor_rr_visual'>
        <pose>0 0 0 0 0 0</pose>
        <geometry>
          <mesh>
            <scale>1 1 1</scale>
            <uri>model://description/meshes/link_castor_rr.STL</uri>
          </mesh>
        </geometry>
        <material>
          <script>
            <name>Gazebo/Blue</name>
            <uri>file://media/materials/scripts/gazebo.material</uri>
          </script>
        </material>
      </visual>
    </link>
    
    <link name='link_lidar'>
      <pose relative_to='joint_lidar'>0 0 0 0 0 0</pose>

      <inertial>
        <pose>0 0 -0.015 0 0 0</pose>
<!--        <mass>0.2</mass>
        <inertia>
          <ixx>0.001</ixx>
          <ixy>0.000</ixy>
          <ixz>0.000</ixz>
          <iyy>0.001</iyy>
          <iyz>0.000</iyz>
          <izz>0.001</izz>
        </inertia>-->
      </inertial>
      
      <collision name='link_lidar_collision'>
        <pose>0 0 0 0 0 0</pose>
        <geometry>
          <mesh>
            <scale>1 1 1</scale>
            <uri>model://description/meshes/link_lidar.STL</uri>
          </mesh>
        </geometry>
      </collision>
      
      <visual name='link_lidar_visual'>
        <pose>0 0 0 0 0 0</pose>
        <geometry>
          <mesh>
            <scale>1 1 1</scale>
            <uri>model://description/meshes/link_lidar.STL</uri>
          </mesh>
        </geometry>
        <material>
          <script>
            <name>Gazebo/Blue</name>
            <uri>file://media/materials/scripts/gazebo.material</uri>
          </script>
        </material>
      </visual>
      
      <sensor name="uvc_robot_v3_lidar" type="ray">
        <always_on>true</always_on>
        <visualize>true</visualize>
        <pose>0 0 0 0 0 0</pose>
        <update_rate>25</update_rate>
        <ray>
          <scan>
            <horizontal>
              <samples>600</samples>
              <resolution>0.500000</resolution>
              <min_angle>-2.6179917</min_angle>
              <max_angle>2.6179917</max_angle>
            </horizontal>
          </scan>
          <range>
            <min>0.100000</min>
            <max>20.000000</max>
            <resolution>0.010000</resolution>
          </range>
          <noise>
            <type>gaussian</type>
            <mean>0.0</mean>
            <stddev>0.01</stddev>
          </noise>
        </ray>
        <plugin name="uvc_robot_v3_laserscan" filename="libgazebo_ros_ray_sensor.so">
          <ros>
            <!-- <namespace>/tb3</namespace> -->
            <remapping>~/out:=scan</remapping>
          </ros>
          <output_type>sensor_msgs/LaserScan</output_type>
          <frame_name>lidar_frame</frame_name>
        </plugin>
      </sensor>
    </link>

  <!-- ********************* All Joints ********************* -->
  <joint name="base_joint" type="fixed">
    <pose relative_to='base_footprint'>0 0 0.075 0 0 0</pose>
    <parent>base_footprint</parent>
    <child>base_link</child>
  </joint>

    <joint name='joint_left' type='revolute'>
      <pose relative_to='base_link'>0 0.35 0.0249 0 0 0</pose>
      <parent>base_link</parent>
      <child>link_left</child>
      <axis>
        <xyz>0 -1 0</xyz>
        <limit>
          <effort>6</effort>
          <velocity>1.2</velocity>
          <lower>-1e+16</lower>
          <upper>1e+16</upper>
        </limit>
        <dynamics>
          <spring_reference>0</spring_reference>
          <spring_stiffness>0</spring_stiffness>
        </dynamics>
      </axis>
    </joint>

    <joint name='joint_right' type='revolute'>
      <pose relative_to='base_link'>0 -0.35 0.0249 0 0 0</pose>
      <parent>base_link</parent>
      <child>link_right</child>
      <axis>
        <xyz>0 -1 0</xyz>
        <limit>
          <effort>6</effort>
          <velocity>1.2</velocity>
          <lower>-1e+16</lower>
          <upper>1e+16</upper>
        </limit>
        <dynamics>
          <spring_reference>0</spring_reference>
          <spring_stiffness>0</spring_stiffness>
        </dynamics>
      </axis>
    </joint>

    <joint name='joint_castor_fl' type='fixed'>
      <pose relative_to='base_link'>-0.37307 -0.22458 0 0 0 3.1416</pose>
      <parent>base_link</parent>
      <child>link_castor_fl</child>
      <axis>
        <xyz>0 0 0</xyz>
      </axis>
    </joint>

    <joint name='joint_castor_fr' type='fixed'>
      <pose relative_to='base_link'>-0.37307 0.22458 0 0 0 3.1416</pose>
      <parent>base_link</parent>
      <child>link_castor_fr</child>
      <axis>
        <xyz>0 0 0</xyz>
      </axis>
    </joint>

    <joint name='joint_castor_rl' type='fixed'>
      <pose relative_to='base_link'>0.37307 -0.22458 0 0 0 3.1416</pose>
      <parent>base_link</parent>
      <child>link_castor_rl</child>
      <axis>
        <xyz>0 0 0</xyz>
      </axis>
    </joint>

    <joint name='joint_castor_rr' type='fixed'>
      <pose relative_to='base_link'>0.37307 0.22458 0 0 0 3.1416</pose>
      <parent>base_link</parent>
      <child>link_castor_rr</child>
      <axis>
        <xyz>0 0 0</xyz>
      </axis>
    </joint>
    
    <joint name='joint_lidar' type='fixed'>
      <pose relative_to='base_link'>-0.39838 -0.0006013 0.21 0 0 3.14159</pose>
      <parent>base_link</parent>
      <child>link_lidar</child>
    </joint>

  <!-- ********************* All Plugins ********************* -->
    <plugin name="uvc_robot_differential_drive_controller" filename="libgazebo_ros_diff_drive.so">
      <update_rate>10</update_rate>
      <left_joint>joint_left</left_joint>
      <right_joint>joint_right</right_joint>
      <wheel_separation>0.6</wheel_separation>
      <wheel_diameter>0.3</wheel_diameter>
      <wheel_torque>6</wheel_torque>
      <wheel_acceleration>1.0</wheel_acceleration>
      <command_topic>cmd_vel</command_topic>
      <odometry_topic>odom</odometry_topic>
      <odometry_frame>odom</odometry_frame>
      <robot_base_frame>base_footprint</robot_base_frame>
      <publish_odom>true</publish_odom>
      <publish_odom_tf>false</publish_odom_tf>
      <publish_wheel_tf>false</publish_wheel_tf>
      <!-- Odometry source, 0 for ENCODER, 1 for WORLD, defaults to WORLD -->
      <odometry_source>1</odometry_source>
      <!--<ros>
        <remapping>odom:=wheel/odometry</remapping>
      </ros>-->
    </plugin>

    <plugin name="uvc_robot_v3_joint_state" filename="libgazebo_ros_joint_state_publisher.so">
      <ros>
        <remapping>~/out:=joint_states</remapping>
      </ros>
      <update_rate>10</update_rate>
      <joint_name>joint_left</joint_name>
      <joint_name>joint_right</joint_name>
    </plugin>
    
    
    
    
  </model>
</sdf>
