<?xml version="1.0" encoding="utf-8"?>
<!-- This URDF was automatically created by SolidWorks to URDF Exporter! Originally created by Stephen Brawner (brawner@gmail.com) 
     Commit Version: 1.6.0-4-g7f85cfe  Build Version: 1.6.7995.38578
     For more information, please see http://wiki.ros.org/sw_urdf_exporter -->
<robot
  name="DCMachine_ChassisAssy2">
  <!-- Define the center of the main robot chassis projected on the ground -->	
  <link name="base_footprint"/>
  
  <link
    name="base_link"><!-- name="Chassis2"> -->
    <inertial>
      <origin
        xyz="-0.0394144455978167 -0.000852095569377779 0.243871805092808"
        rpy="0 0 0" />
      <mass
        value="8.8576262185832" />
      <inertia
        ixx="0.617051233750544"
        ixy="-2.10490036663428E-05"
        ixz="0.158174809864285"
        iyy="0.892390477879212"
        iyz="2.69481890395974E-05"
        izz="0.755671696026969" />
    </inertial>
    <visual>
      <origin
        xyz="0 0 0"
        rpy="0 0 0" />
      <geometry>
        <mesh
          filename="package://suru_v1_0/meshes/Chassis2.STL" />
      </geometry>
      <material
        name="">
        <color
          rgba="0.796078431372549 0.823529411764706 0.937254901960784 1" />
      </material>
    </visual>
    <collision>
      <origin
        xyz="0 0 0"
        rpy="0 0 0" />
      <geometry>
        <mesh
          filename="package://suru_v1_0/meshes/Chassis2.STL" />
      </geometry>
    </collision>
  </link>
  <joint 
    name="base_joint" 
    type="fixed">
    <parent 
      link="base_footprint"/>
    <child 
      link="base_link" />
    <origin 
      xyz="0.0 0.0 0.0"
      rpy="0 0 0"/>
  </joint>
  <link
    name="BackCastorBkt">
    <inertial>
      <origin
        xyz="-0.020171 -7.7009E-17 -0.037604"
        rpy="0 0 0" />
      <mass
        value="0.038797" />
      <inertia
        ixx="5.6327E-05"
        ixy="-1.6026E-20"
        ixz="-6.8167E-06"
        iyy="5.0448E-05"
        iyz="-1.3304E-20"
        izz="2.9319E-05" />
    </inertial>
    <visual>
      <origin
        xyz="0 0 0"
        rpy="0 0 0" />
      <geometry>
        <mesh
          filename="package://suru_v1_0/meshes/BackCastorBkt.STL" />
      </geometry>
      <material
        name="">
        <color
          rgba="0.79608 0.82353 0.93725 1" />
      </material>
    </visual>
    <collision>
      <origin
        xyz="0 0 0"
        rpy="0 0 0" />
      <geometry>
        <mesh
          filename="package://suru_v1_0/meshes/BackCastorBkt.STL" />
      </geometry>
    </collision>
  </link>
  <joint
    name="BackWheelBkt"
    type="fixed"><!-- type="continuous"> -->
    <origin
      xyz="-0.4125 0 0.001"
      rpy="0 0 0" />
    <parent
      link="base_link" />
    <child
      link="BackCastorBkt" />
    <axis
      xyz="0 0 1" />
    <!-- <limit
      effort="10"
      velocity="10" />
    <dynamics
      damping="0.1"
      friction="0.1" /> -->
  </joint>
  <link
    name="BackCastor">
    <inertial>
      <origin
        xyz="5.5511E-17 3.4694E-18 -0.02"
        rpy="0 0 0" />
      <mass
        value="0.1562" />
      <inertia
        ixx="6.9409E-05"
        ixy="1.6844E-08"
        ixz="-4.565E-22"
        iyy="6.9452E-05"
        iyz="-7.6894E-22"
        izz="0.00010061" />
    </inertial>
    <visual>
      <origin
        xyz="0 0 0"
        rpy="0 0 0" />
      <geometry>
        <mesh
          filename="package://suru_v1_0/meshes/BackCastor.STL" />
      </geometry>
      <material
        name="">
        <color
          rgba="0.79608 0.82353 0.93725 1" />
      </material>
    </visual>
    <collision>
      <origin
        xyz="0 0 0"
        rpy="0 0 0" />
      <geometry>
        <mesh
          filename="package://suru_v1_0/meshes/BackCastor.STL" />
      </geometry>
    </collision>
  </link>
  <joint
    name="BackWheel"
    type="fixed"><!-- type="continuous"> -->
    <origin
      xyz="-0.0305 -0.02 -0.0935"
      rpy="1.5708 0 0" />
    <parent
      link="BackCastorBkt" />
    <child
      link="BackCastor" />
    <axis
      xyz="0 0 -1" />
    <!-- <limit
      effort="10"
      velocity="10" />
    <dynamics
      damping="0.1"
      friction="0.1" /> -->
  </joint>
  <link
    name="LeftDriveWheel">
    <inertial>
      <origin
        xyz="6.9389E-18 -2.7756E-17 0.0275"
        rpy="0 0 0" />
      <mass
        value="1.2472" />
      <inertia
        ixx="0.0032987"
        ixy="1.7618E-19"
        ixz="-3.5891E-19"
        iyy="0.0032987"
        iyz="7.8613E-22"
        izz="0.0062599" />
    </inertial>
    <visual>
      <origin
        xyz="0 0 0"
        rpy="0 0 0" />
      <geometry>
        <mesh
          filename="package://suru_v1_0/meshes/LeftDriveWheel.STL" />
      </geometry>
      <material
        name="">
        <color
          rgba="0.79608 0.82353 0.93725 1" />
      </material>
    </visual>
    <collision>
      <origin
        xyz="0 0 0"
        rpy="0 0 0" />
      <geometry>
        <mesh
          filename="package://suru_v1_0/meshes/LeftDriveWheel.STL" />
      </geometry>
    </collision>
  </link>
  <joint
    name="LDWheel"
    type="continuous">
    <origin
      xyz="0 0.3199 0"
      rpy="1.5708 0 0" />
    <parent
      link="base_link" />
    <child
      link="LeftDriveWheel" />
    <axis
      xyz="0 0 -1" />
    <limit
      effort="10"
      velocity="10" />
    <dynamics
      damping="0.1"
      friction="0.1" />
  </joint>
  <link
    name="RightDriveWheel">
    <inertial>
      <origin
        xyz="-2.0817E-17 -2.7756E-17 -0.0275"
        rpy="0 0 0" />
      <mass
        value="1.2472" />
      <inertia
        ixx="0.0032987"
        ixy="2.4395E-19"
        ixz="2.1555E-20"
        iyy="0.0032987"
        iyz="7.2704E-20"
        izz="0.0062599" />
    </inertial>
    <visual>
      <origin
        xyz="0 0 0"
        rpy="0 0 0" />
      <geometry>
        <mesh
          filename="package://suru_v1_0/meshes/RightDriveWheel.STL" />
      </geometry>
      <material
        name="">
        <color
          rgba="0.79608 0.82353 0.93725 1" />
      </material>
    </visual>
    <collision>
      <origin
        xyz="0 0 0"
        rpy="0 0 0" />
      <geometry>
        <mesh
          filename="package://suru_v1_0/meshes/RightDriveWheel.STL" />
      </geometry>
    </collision>
  </link>
  <joint
    name="RDWheel"
    type="continuous">
    <origin
      xyz="0 -0.32 0"
      rpy="1.5708 0 0" />
    <parent
      link="base_link" />
    <child
      link="RightDriveWheel" />
    <axis
      xyz="0 0 1" />
    <limit
      effort="10"
      velocity="10" />
    <dynamics
      damping="0.1"
      friction="0.1" />
  </joint>
  <link
    name="FrontLeftCastorBkt">
    <inertial>
      <origin
        xyz="-0.01454 -2.7756E-17 -0.024477"
        rpy="0 0 0" />
      <mass
        value="0.0077113" />
      <inertia
        ixx="4.1898E-06"
        ixy="1.9154E-21"
        ixz="-4.3998E-07"
        iyy="3.8052E-06"
        iyz="-4.0431E-21"
        izz="2.1972E-06" />
    </inertial>
    <visual>
      <origin
        xyz="0 0 0"
        rpy="0 0 0" />
      <geometry>
        <mesh
          filename="package://suru_v1_0/meshes/FrontLeftCastorBkt.STL" />
      </geometry>
      <material
        name="">
        <color
          rgba="0.79608 0.82353 0.93725 1" />
      </material>
    </visual>
    <collision>
      <origin
        xyz="0 0 0"
        rpy="0 0 0" />
      <geometry>
        <mesh
          filename="package://suru_v1_0/meshes/FrontLeftCastorBkt.STL" />
      </geometry>
    </collision>
  </link>
  <joint
    name="FLCastorBkt"
    type="fixed"><!-- type="continuous"> -->
    <origin
      xyz="0.3275 0.207 -0.0025"
      rpy="0 0 0" />
    <parent
      link="base_link" />
    <child
      link="FrontLeftCastorBkt" />
    <axis
      xyz="0 0 1" />
    <!-- <limit
      effort="10"
      velocity="10" />
    <dynamics
      damping="0.1"
      friction="0.1" /> -->
  </joint>
  <link
    name="FrontLeftCastor">
    <inertial>
      <origin
        xyz="0 6.9389E-18 0.0125"
        rpy="0 0 0" />
      <mass
        value="0.022649" />
      <inertia
        ixx="2.8628E-06"
        ixy="3.2034E-09"
        ixz="-1.227E-22"
        iyy="2.8638E-06"
        iyz="8.9544E-23"
        izz="3.4876E-06" />
    </inertial>
    <visual>
      <origin
        xyz="0 0 0"
        rpy="0 0 0" />
      <geometry>
        <mesh
          filename="package://suru_v1_0/meshes/FrontLeftCastor.STL" />
      </geometry>
      <material
        name="">
        <color
          rgba="0.79608 0.82353 0.93725 1" />
      </material>
    </visual>
    <collision>
      <origin
        xyz="0 0 0"
        rpy="0 0 0" />
      <geometry>
        <mesh
          filename="package://suru_v1_0/meshes/FrontLeftCastor.STL" />
      </geometry>
    </collision>
  </link>
  <joint
    name="FLCastor"
    type="fixed"><!-- type="continuous"> -->
    <origin
      xyz="-0.02 0.0125 -0.0555"
      rpy="1.5708 0 0" />
    <parent
      link="FrontLeftCastorBkt" />
    <child
      link="FrontLeftCastor" />
    <axis
      xyz="0 0 1" />
    <!-- <limit
      effort="10"
      velocity="10" />
    <dynamics
      damping="0.1"
      friction="0.1" /> -->
  </joint>
  <link
    name="FrontRightCastorBkt">
    <inertial>
      <origin
        xyz="-0.01454 0 -0.024477"
        rpy="0 0 0" />
      <mass
        value="0.0077113" />
      <inertia
        ixx="4.1898E-06"
        ixy="3.5563E-21"
        ixz="-4.3998E-07"
        iyy="3.8052E-06"
        iyz="-1.1338E-21"
        izz="2.1972E-06" />
    </inertial>
    <visual>
      <origin
        xyz="0 0 0"
        rpy="0 0 0" />
      <geometry>
        <mesh
          filename="package://suru_v1_0/meshes/FrontRightCastorBkt.STL" />
      </geometry>
      <material
        name="">
        <color
          rgba="0.79608 0.82353 0.93725 1" />
      </material>
    </visual>
    <collision>
      <origin
        xyz="0 0 0"
        rpy="0 0 0" />
      <geometry>
        <mesh
          filename="package://suru_v1_0/meshes/FrontRightCastorBkt.STL" />
      </geometry>
    </collision>
  </link>
  <joint
    name="FRCastorBkt"
    type="fixed"><!-- type="continuous"> -->
    <origin
      xyz="0.3275 -0.207 -0.0025"
      rpy="0 0 0" />
    <parent
      link="base_link" />
    <child
      link="FrontRightCastorBkt" />
    <axis
      xyz="0 0 1" />
    <!-- <limit
      effort="10"
      velocity="10" />
    <dynamics
      damping="0.1"
      friction="0.1" /> -->
  </joint>
  <link
    name="FrontRightCastor">
    <inertial>
      <origin
        xyz="5.5511E-17 6.9389E-18 -0.0125"
        rpy="0 0 0" />
      <mass
        value="0.022649" />
      <inertia
        ixx="2.8601E-06"
        ixy="-5.785E-10"
        ixz="-9.0247E-22"
        iyy="2.8665E-06"
        iyz="-3.1415E-23"
        izz="3.4876E-06" />
    </inertial>
    <visual>
      <origin
        xyz="0 0 0"
        rpy="0 0 0" />
      <geometry>
        <mesh
          filename="package://suru_v1_0/meshes/FrontRightCastor.STL" />
      </geometry>
      <material
        name="">
        <color
          rgba="0.79608 0.82353 0.93725 1" />
      </material>
    </visual>
    <collision>
      <origin
        xyz="0 0 0"
        rpy="0 0 0" />
      <geometry>
        <mesh
          filename="package://suru_v1_0/meshes/FrontRightCastor.STL" />
      </geometry>
    </collision>
  </link>
  <joint
    name="FRCastor"
    type="fixed"><!-- type="continuous"> -->
    <origin
      xyz="-0.02 -0.0125 -0.0555"
      rpy="1.5708 0 0" />
    <parent
      link="FrontRightCastorBkt" />
    <child
      link="FrontRightCastor" />
    <axis
      xyz="0 0 -1" />
    <!-- <limit
      effort="10"
      velocity="10" />
    <dynamics
      damping="0.1"
      friction="0.1" /> -->
  </joint>
</robot>